Traceback (most recent call last):
  File "/Users/clintguymon/opt/anaconda3/envs/jupiterbook/lib/python3.9/site-packages/jupyter_cache/executors/utils.py", line 58, in single_nb_execution
    executenb(
  File "/Users/clintguymon/opt/anaconda3/envs/jupiterbook/lib/python3.9/site-packages/nbclient/client.py", line 1305, in execute
    return NotebookClient(nb=nb, resources=resources, km=km, **kwargs).execute()
  File "/Users/clintguymon/opt/anaconda3/envs/jupiterbook/lib/python3.9/site-packages/jupyter_core/utils/__init__.py", line 166, in wrapped
    return loop.run_until_complete(inner)
  File "/Users/clintguymon/opt/anaconda3/envs/jupiterbook/lib/python3.9/asyncio/base_events.py", line 647, in run_until_complete
    return future.result()
  File "/Users/clintguymon/opt/anaconda3/envs/jupiterbook/lib/python3.9/site-packages/nbclient/client.py", line 705, in async_execute
    await self.async_execute_cell(
  File "/Users/clintguymon/opt/anaconda3/envs/jupiterbook/lib/python3.9/site-packages/nbclient/client.py", line 1058, in async_execute_cell
    await self._check_raise_for_error(cell, cell_index, exec_reply)
  File "/Users/clintguymon/opt/anaconda3/envs/jupiterbook/lib/python3.9/site-packages/nbclient/client.py", line 914, in _check_raise_for_error
    raise CellExecutionError.from_cell_and_msg(cell, exec_reply_content)
nbclient.exceptions.CellExecutionError: An error occurred while executing the following cell:
------------------

# Debug the following code which is supposed to find 
# the transpose of the matrix

A = np.array([[ 5,  8,  4,  2],
              [ 1, -6,  5, -7],
              [-2,  2, -9,  1],
              [-3,  5, -8,  7]])

#Print the size of the matrix
print(A.shape)

A_transpose = np.zeros(4) #initialize a transpose matrix with zeroes (to fill out manually)

for i in range(2):
    for j in range(4):
        A_transpose[j] = A[i]

print(A_transpose-A.T) #check if the transpose is correct, should be array of zeros
#A.T is the transpose of A

------------------

----- stdout -----
(4, 4)
------------------

[0;31m---------------------------------------------------------------------------[0m
[0;31mTypeError[0m                                 Traceback (most recent call last)
[0;31mTypeError[0m: only length-1 arrays can be converted to Python scalars

The above exception was the direct cause of the following exception:

[0;31mValueError[0m                                Traceback (most recent call last)
Cell [0;32mIn[2], line 16[0m
[1;32m     14[0m [38;5;28;01mfor[39;00m i [38;5;129;01min[39;00m [38;5;28mrange[39m([38;5;241m2[39m):
[1;32m     15[0m     [38;5;28;01mfor[39;00m j [38;5;129;01min[39;00m [38;5;28mrange[39m([38;5;241m4[39m):
[0;32m---> 16[0m         [43mA_transpose[49m[43m[[49m[43mj[49m[43m][49m [38;5;241m=[39m A[i]
[1;32m     18[0m [38;5;28mprint[39m(A_transpose[38;5;241m-[39mA[38;5;241m.[39mT) [38;5;66;03m#check if the transpose is correct, should be array of zeros[39;00m
[1;32m     19[0m [38;5;66;03m#A.T is the transpose of A[39;00m

[0;31mValueError[0m: setting an array element with a sequence.

