Traceback (most recent call last):
  File "/Users/clintguymon/opt/anaconda3/envs/jupiterbook/lib/python3.9/site-packages/jupyter_cache/executors/utils.py", line 58, in single_nb_execution
    executenb(
  File "/Users/clintguymon/opt/anaconda3/envs/jupiterbook/lib/python3.9/site-packages/nbclient/client.py", line 1305, in execute
    return NotebookClient(nb=nb, resources=resources, km=km, **kwargs).execute()
  File "/Users/clintguymon/opt/anaconda3/envs/jupiterbook/lib/python3.9/site-packages/jupyter_core/utils/__init__.py", line 166, in wrapped
    return loop.run_until_complete(inner)
  File "/Users/clintguymon/opt/anaconda3/envs/jupiterbook/lib/python3.9/asyncio/base_events.py", line 647, in run_until_complete
    return future.result()
  File "/Users/clintguymon/opt/anaconda3/envs/jupiterbook/lib/python3.9/site-packages/nbclient/client.py", line 705, in async_execute
    await self.async_execute_cell(
  File "/Users/clintguymon/opt/anaconda3/envs/jupiterbook/lib/python3.9/site-packages/nbclient/client.py", line 1058, in async_execute_cell
    await self._check_raise_for_error(cell, cell_index, exec_reply)
  File "/Users/clintguymon/opt/anaconda3/envs/jupiterbook/lib/python3.9/site-packages/nbclient/client.py", line 914, in _check_raise_for_error
    raise CellExecutionError.from_cell_and_msg(cell, exec_reply_content)
nbclient.exceptions.CellExecutionError: An error occurred while executing the following cell:
------------------
x = 5 #setting a variable x = 5. This is a global variable as it is outside of any function or class. 
# I can use this variable anywhere in the code, including inside a function or class.

def afunction(input):
    newval = input + x #using the x global variable inside the function.
    x = 10 #setting a new value for x. This will yield an error.
    return newval

print(f'The afunction value with an input of 43 is {afunction(43)}. The global x value is still {x}.')
------------------


[0;31m---------------------------------------------------------------------------[0m
[0;31mUnboundLocalError[0m                         Traceback (most recent call last)
Cell [0;32mIn[1], line 9[0m
[1;32m      6[0m     x [38;5;241m=[39m [38;5;241m10[39m [38;5;66;03m#setting a new value for x. This will yield an error.[39;00m
[1;32m      7[0m     [38;5;28;01mreturn[39;00m newval
[0;32m----> 9[0m [38;5;28mprint[39m([38;5;124mf[39m[38;5;124m'[39m[38;5;124mThe afunction value with an input of 43 is [39m[38;5;132;01m{[39;00m[43mafunction[49m[43m([49m[38;5;241;43m43[39;49m[43m)[49m[38;5;132;01m}[39;00m[38;5;124m. The global x value is still [39m[38;5;132;01m{[39;00mx[38;5;132;01m}[39;00m[38;5;124m.[39m[38;5;124m'[39m)

Cell [0;32mIn[1], line 5[0m, in [0;36mafunction[0;34m(input)[0m
[1;32m      4[0m [38;5;28;01mdef[39;00m [38;5;21mafunction[39m([38;5;28minput[39m):
[0;32m----> 5[0m     newval [38;5;241m=[39m [38;5;28minput[39m [38;5;241m+[39m [43mx[49m [38;5;66;03m#using the x global variable inside the function.[39;00m
[1;32m      6[0m     x [38;5;241m=[39m [38;5;241m10[39m [38;5;66;03m#setting a new value for x. This will yield an error.[39;00m
[1;32m      7[0m     [38;5;28;01mreturn[39;00m newval

[0;31mUnboundLocalError[0m: local variable 'x' referenced before assignment

