Traceback (most recent call last):
  File "/Users/clintguymon/opt/anaconda3/envs/jupiterbook/lib/python3.9/site-packages/jupyter_cache/executors/utils.py", line 58, in single_nb_execution
    executenb(
  File "/Users/clintguymon/opt/anaconda3/envs/jupiterbook/lib/python3.9/site-packages/nbclient/client.py", line 1305, in execute
    return NotebookClient(nb=nb, resources=resources, km=km, **kwargs).execute()
  File "/Users/clintguymon/opt/anaconda3/envs/jupiterbook/lib/python3.9/site-packages/jupyter_core/utils/__init__.py", line 166, in wrapped
    return loop.run_until_complete(inner)
  File "/Users/clintguymon/opt/anaconda3/envs/jupiterbook/lib/python3.9/asyncio/base_events.py", line 647, in run_until_complete
    return future.result()
  File "/Users/clintguymon/opt/anaconda3/envs/jupiterbook/lib/python3.9/site-packages/nbclient/client.py", line 705, in async_execute
    await self.async_execute_cell(
  File "/Users/clintguymon/opt/anaconda3/envs/jupiterbook/lib/python3.9/site-packages/nbclient/client.py", line 1058, in async_execute_cell
    await self._check_raise_for_error(cell, cell_index, exec_reply)
  File "/Users/clintguymon/opt/anaconda3/envs/jupiterbook/lib/python3.9/site-packages/nbclient/client.py", line 914, in _check_raise_for_error
    raise CellExecutionError.from_cell_and_msg(cell, exec_reply_content)
nbclient.exceptions.CellExecutionError: An error occurred while executing the following cell:
------------------
2**kinetic_energy_p
------------------


[0;31m---------------------------------------------------------------------------[0m
[0;31mDimensionalityError[0m                       Traceback (most recent call last)
Cell [0;32mIn[5], line 1[0m
[0;32m----> 1[0m [38;5;241;43m2[39;49m[38;5;241;43m*[39;49m[38;5;241;43m*[39;49m[43mkinetic_energy_p[49m

File [0;32m~/opt/anaconda3/envs/jupiterbook/lib/python3.9/site-packages/pint/facets/plain/quantity.py:100[0m, in [0;36mcheck_implemented.<locals>.wrapped[0;34m(self, *args, **kwargs)[0m
[1;32m     98[0m [38;5;28;01melif[39;00m [38;5;28misinstance[39m(other, [38;5;28mlist[39m) [38;5;129;01mand[39;00m other [38;5;129;01mand[39;00m [38;5;28misinstance[39m(other[[38;5;241m0[39m], [38;5;28mtype[39m([38;5;28mself[39m)):
[1;32m     99[0m     [38;5;28;01mreturn[39;00m [38;5;28mNotImplemented[39m
[0;32m--> 100[0m [38;5;28;01mreturn[39;00m [43mf[49m[43m([49m[38;5;28;43mself[39;49m[43m,[49m[43m [49m[38;5;241;43m*[39;49m[43margs[49m[43m,[49m[43m [49m[38;5;241;43m*[39;49m[38;5;241;43m*[39;49m[43mkwargs[49m[43m)[49m

File [0;32m~/opt/anaconda3/envs/jupiterbook/lib/python3.9/site-packages/pint/facets/plain/quantity.py:1264[0m, in [0;36mPlainQuantity.__rpow__[0;34m(self, other)[0m
[1;32m   1262[0m [38;5;28;01melse[39;00m:
[1;32m   1263[0m     [38;5;28;01mif[39;00m [38;5;129;01mnot[39;00m [38;5;28mself[39m[38;5;241m.[39mdimensionless:
[0;32m-> 1264[0m         [38;5;28;01mraise[39;00m DimensionalityError([38;5;28mself[39m[38;5;241m.[39m_units, [38;5;124m"[39m[38;5;124mdimensionless[39m[38;5;124m"[39m)
[1;32m   1265[0m     new_self [38;5;241m=[39m [38;5;28mself[39m[38;5;241m.[39mto_root_units()
[1;32m   1266[0m     [38;5;28;01mreturn[39;00m other[38;5;241m*[39m[38;5;241m*[39mnew_self[38;5;241m.[39m_magnitude

[0;31mDimensionalityError[0m: Cannot convert from 'kilogram * mile ** 2 / hour ** 2' to 'dimensionless'

